Workbook

Sheet Step 1
A6: Date | B6: Close | C6: MA1 | D6: MA2 | E6: MA3
A7: 08/02/2024 | B7: 11 | C7: =AVERAGE(B7:B25) -> 14.513158 | D7: =AVERAGE(B7:B45) -> 22.428462 | E7: =AVERAGE(B7:B105) -> 38.001616
A8: 07/31/2024 | B8: 11.42 | C8: =AVERAGE(B8:B26) -> 15.153158 | D8: =AVERAGE(B8:B46) -> 23.234103 | E8: =AVERAGE(B8:B106) -> 38.448081
A9: 06/28/2024 | B9: 10.39 | C9: =AVERAGE(B9:B27) -> 15.440526 | D9: =AVERAGE(B9:B47) -> 23.993077 | E9: =AVERAGE(B9:B107) -> 38.897475
A10: 05/31/2024 | B10: 11.91 | C10: =AVERAGE(B10:B28) -> 15.950526 | D10: =AVERAGE(B10:B48) -> 24.883077 | E10: =AVERAGE(B10:B108) -> 39.34899
A11: 04/30/2024 | B11: 11.39 | C11: =AVERAGE(B11:B29) -> 16.287895 | D11: =AVERAGE(B11:B49) -> 26.231282 | E11: =AVERAGE(B11:B109) -> 39.717374
A12: 03/28/2024 | B12: 11.77 | C12: =AVERAGE(B12:B30) -> 16.690526 | D12: =AVERAGE(B12:B50) -> 27.182821 | E12: =AVERAGE(B12:B110) -> 40.082121
A13: 02/29/2024 | B13: 11.04 | C13: =AVERAGE(B13:B31) -> 17.302105 | D13: =AVERAGE(B13:B51) -> 27.83641 | E13: =AVERAGE(B13:B111) -> 40.439293
A14: 01/31/2024 | B14: 14.59 | C14: =AVERAGE(B14:B32) -> 17.965789 | D14: =AVERAGE(B14:B52) -> 28.457949 | E14: =AVERAGE(B14:B112) -> 40.837677
A15: 12/29/2023 | B15: 14.79 | C15: =AVERAGE(B15:B33) -> 18.496842 | D15: =AVERAGE(B15:B53) -> 28.81641 | E15: =AVERAGE(B15:B113) -> 41.160202
A16: 11/30/2023 | B16: 14.37 | C16: =AVERAGE(B16:B34) -> 19.525263 | D16: =AVERAGE(B16:B54) -> 29.155385 | E16: =AVERAGE(B16:B114) -> 41.413838
A17: 10/31/2023 | B17: 10.88 | C17: =AVERAGE(B17:B35) -> 20.301579 | D17: =AVERAGE(B17:B55) -> 29.501026 | E17: =AVERAGE(B17:B115) -> 41.725657
A18: 09/29/2023 | B18: 12.9 | C18: =AVERAGE(B18:B36) -> 21.718947 | D18: =AVERAGE(B18:B56) -> 29.890513 | E18: =AVERAGE(B18:B116) -> 42.155859
... A127: 08/29/2014 | B127: 59.29 | C127: =AVERAGE(B127:B145) -> 59.29 | D127: =AVERAGE(B127:B165) -> 59.29 | E127: =AVERAGE(B127:B225) -> 59.29

Sheet Step 2
A1: Historical Pricing
A2: Date | B2: Close | C2: NAICS | D2: Year | E2: TB | F2: R_PARA | G2: R_NAICS | H2: R_TB | I2: ER_PARA | J2: ER_NAICS | L2: beta | M2: =LINEST(I3:I122,J3:J122,FALSE) -> 0.85227577
A3: 08/02/2024 | B3: 11 | C3: 1930.67 | D3: 2024-08 | E3: 5.1 | F3: =(B3-B4)/B4 -> -0.036777583 | G3: =(C3-C4)/C4 -> -0.036288853 | H3: =(E3-E4)/E4 -> -0.019230769 | I3: =F3-H3 -> -0.017546814 | J3: =F3-G3 -> -0.00048872991 | L3: E(r) | M3: =(5.1+0.852275767*(-0.00049))/100 -> 0.050995824
A4: 07/31/2024 | B4: 11.42 | C4: 2003.37 | D4: 2024-07 | E4: 5.2 | F4: =(B4-B5)/B5 -> 0.099133782 | G4: =(C4-C5)/C5 -> 0.015758332 | H4: =(E4-E5)/E5 -> -0.0076335878 | I4: =F4-H4 -> 0.10676737 | J4: =F4-G4 -> 0.083375451
A5: 06/28/2024 | B5: 10.39 | C5: 1972.29 | D5: 2024-06 | E5: 5.24 | F5: =(B5-B6)/B6 -> -0.12762385 | G5: =(C5-C6)/C6 -> -0.022675355 | H5: =(E5-E6)/E6 -> -0.0019047619 | I5: =F5-H5 -> -0.12571908 | J5: =F5-G5 -> -0.10494849 | L5: Current Price | M5: =B3 -> 11 | O5: =(0.3485-0.2819905) -> 0.0665095
A6: 05/31/2024 | B6: 11.91 | C6: 2018.05 | D6: 2024-05 | E6: 5.25 | F6: =(B6-B7)/B7 -> 0.045654083 | G6: =(C6-C7)/C7 -> -0.023946101 | H6: =(E6-E7)/E7 -> 0.0019083969 | I6: =F6-H6 -> 0.043745686 | J6: =F6-G6 -> 0.069600183 | L6: Exp Price | M6: =M5*(1+M3) -> 11.560954
A7: 04/30/2024 | B7: 11.39 | C7: 2067.56 | D7: 2024-04 | E7: 5.24 | F7: =(B7-B8)/B8 -> -0.032285472 | G7: =(C7-C8)/C8 -> 0.0042061295 | H7: =(E7-E8)/E8 -> 0 | I7: =F7-H7 -> -0.032285472 | J7: =F7-G7 -> -0.036491601
A8: 03/28/2024 | B8: 11.77 | C8: 2058.9 | D8: 2024-03 | E8: 5.24 | F8: =(B8-B9)/B9 -> 0.066123188 | G8: =(C8-C9)/C9 -> 0.032035248 | H8: =(E8-E9)/E9 -> 0 | I8: =F8-H8 -> 0.066123188 | J8: =F8-G8 -> 0.03408794 | L8: Trading Str. | M8: long position
A9: 02/29/2024 | B9: 11.04 | C9: 1994.99 | D9: 2024-02 | E9: 5.24 | F9: =(B9-B10)/B10 -> -0.24331734 | G9: =(C9-C10)/C10 -> -0.052036113 | H9: =(E9-E10)/E10 -> 0.0038314176 | I9: =F9-H9 -> -0.24714876 | J9: =F9-G9 -> -0.19128123 | L9: Sell with min | M9: 11.3
A10: 01/31/2024 | B10: 14.59 | C10: 2104.5 | D10: 2024-01 | E10: 5.22 | F10: =(B10-B11)/B11 -> -0.01352265 | G10: =(C10-C11)/C11 -> 0.017704036 | H10: =(E10-E11)/E11 -> -0.0038167939 | I10: =F10-H10 -> -0.0097058565 | J10: =F10-G10 -> -0.031226687 | L10: Then buy at | M10: 10.9
A11: 12/29/2023 | B11: 14.79 | C11: 2067.89 | D11: 2023-12 | E11: 5.24 | F11: =(B11-B12)/B12 -> 0.029227557 | G11: =(C11-C12)/C12 -> -0.0084487727 | H11: =(E11-E12)/E12 -> -0.0056925996 | I11: =F11-H11 -> 0.034920157 | J11: =F11-G11 -> 0.03767633
A12: 11/30/2023 | B12: 14.37 | C12: 2085.51 | D12: 2023-11 | E12: 5.27 | F12: =(B12-B13)/B13 -> 0.32077206 | G12: =(C12-C13)/C13 -> -0.010382511 | H12: =(E12-E13)/E13 -> -0.013108614 | I12: =F12-H12 -> 0.33388067 | J12: =F12-G12 -> 0.33115457 | L12: Test Trading Str.
A13: 10/31/2023 | B13: 10.88 | C13: 2107.39 | D13: 2023-10 | E13: 5.34 | F13: =(B13-B14)/B14 -> -0.15658915 | G13: =(C13-C14)/C14 -> 0.021462743 | H13: =(E13-E14)/E14 -> 0.0037593985 | I13: =F13-H13 -> -0.16034855 | J13: =F13-G13 -> -0.17805189 | L13: Sell | M13: 45506
A14: 09/29/2023 | B14: 12.9 | C14: 2063.11 | D14: 2023-09 | E14: 5.32 | F14: =(B14-B15)/B15 -> -0.14512922 | G14: =(C14-C15)/C15 -> -0.019359837 | H14: =(E14-E15)/E15 -> 0.0037735849 | I14: =F14-H14 -> -0.14890281 | J14: =F14-G14 -> -0.12576939 | L14: buy | M14: 45506
A15: 08/31/2023 | B15: 15.09 | C15: 2103.84 | D15: 2023-08 | E15: 5.3 | F15: =(B15-B16)/B16 -> -0.05864005 | G15: =(C15-C16)/C16 -> 0.066758612 | H15: =(E15-E16)/E16 -> 0.0095238095 | I15: =F15-H15 -> -0.068163859 | J15: =F15-G15 -> -0.12539866
A16: 07/31/2023 | B16: 16.03 | C16: 1972.18 | D16: 2023-07 | E16: 5.25 | F16: =(B16-B17)/B17 -> 0.0075424261 | G16: =(C16-C17)/C17 -> 0.027161034 | H16: =(E16-E17)/E17 -> 0.01744186 | I16: =F16-H16 -> -0.0098994343 | J16: =F16-G16 -> -0.019618608 | L16: return | M16: =(M9-M10)/M10 -> 0.036697248
A17: 06/30/2023 | B17: 15.91 | C17: 1920.03 | D17: 2023-06 | E17: 5.16 | F17: =(B17-B18)/B18 -> 0.046022354 | G17: =(C17-C18)/C18 -> -0.076624538 | H17: =(E17-E18)/E18 -> 0.0038910506 | I17: =F17-H17 -> 0.042131303 | J17: =F17-G17 -> 0.12264689
A18: 05/31/2023 | B18: 15.21 | C18: 2079.36 | D18: 2023-05 | E18: 5.14 | F18: =(B18-B19)/B19 -> -0.34804972 | G18: =(C18-C19)/C19 -> -0.00050470821 | H18: =(E18-E19)/E19 -> 0.044715447 | I18: =F18-H18 -> -0.39276517 | J18: =F18-G18 -> -0.34754501
A19: 04/28/2023 | B19: 23.33 | C19: 2080.41 | D19: 2023-04 | E19: 4.92 | F19: =(B19-B20)/B20 -> 0.045719408 | G19: =(C19-C20)/C20 -> 0.01784299 | H19: =(E19-E20)/E20 -> 0.049040512 | I19: =F19-H19 -> -0.0033211034 | J19: =F19-G19 -> 0.027876419
A20: 03/31/2023 | B20: 22.31 | C20: 2043.94 | D20: 2023-03 | E20: 4.69 | F20: =(B20-B21)/B21 -> 0.041549953 | G20: =(C20-C21)/C21 -> 0.053446996 | H20: =(E20-E21)/E21 -> 0.0086021505 | I20: =F20-H20 -> 0.032947803 | J20: =F20-G20 -> -0.011897043
A21: 02/28/2023 | B21: 21.42 | C21: 1940.24 | D21: 2023-02 | E21: 4.65 | F21: =(B21-B22)/B22 -> -0.075129534 | G21: =(C21-C22)/C22 -> 0.0041454692 | H21: =(E21-E22)/E22 -> 0.024229075 | I21: =F21-H21 -> -0.099358609 | J21: =F21-G21 -> -0.079275003
A22: 01/31/2023 | B22: 23.16 | C22: 1932.23 | D22: 2023-01 | E22: 4.54 | F22: =(B22-B23)/B23 -> 0.37203791 | G22: =(C22-C23)/C23 -> -0.061905872 | H22: =(E22-E23)/E23 -> 0.068235294 | I22: =F22-H22 -> 0.30380262 | J22: =F22-G22 -> 0.43394379
A23: 12/30/2022 | B23: 16.88 | C23: 2059.74 | D23: 2022-12 | E23: 4.25 | F23: =(B23-B24)/B24 -> -0.15936255 | G23: =(C23-C24)/C24 -> -0.0026921028 | H23: =(E23-E24)/E24 -> 0.024096386 | I23: =F23-H23 -> -0.18345894 | J23: =F23-G23 -> -0.15667045
A24: 11/30/2022 | B24: 20.08 | C24: 2065.3 | D24: 2022-11 | E24: 4.15 | F24: =(B24-B25)/B25 -> 0.096069869 | G24: =(C24-C25)/C25 -> -0.015098047 | H24: =(E24-E25)/E25 -> 0.1155914 | I24: =F24-H24 -> -0.019521529 | J24: =F24-G24 -> 0.11116792
A25: 10/31/2022 | B25: 18.32 | C25: 2096.96 | D25: 2022-10 | E25: 3.72 | F25: =(B25-B26)/B26 -> -0.037815126 | G25: =(C25-C26)/C26 -> -0.00090525333 | H25: =(E25-E26)/E26 -> 0.1884984 | I25: =F25-H25 -> -0.22631353 | J25: =F25-G25 -> -0.036909873
A26: 09/30/2022 | B26: 19.04 | C26: 2098.86 | D26: 2022-09 | E26: 3.13 | F26: =(B26-B27)/B27 -> -0.18597691 | G26: =(C26-C27)/C27 -> -0.034385351 | H26: =(E26-E27)/E27 -> 0.19011407 | I26: =F26-H26 -> -0.37609098 | J26: =F26-G26 -> -0.15159156
A27: 08/31/2022 | B27: 23.39 | C27: 2173.6 | D27: 2022-08 | E27: 2.63 | F27: =(B27-B28)/B28 -> -0.010993658 | G27: =(C27-C28)/C28 -> 0.0012206638 | H27: =(E27-E28)/E28 -> 0.1793722 | I27: =F27-H27 -> -0.19036585 | J27: =F27-G27 -> -0.012214321
A28: 07/29/2022 | B28: 23.65 | C28: 2170.95 | D28: 2022-07 | E28: 2.23 | F28: =(B28-B29)/B29 -> -0.041734198 | G28: =(C28-C29)/C29 -> 0.0012360084 | H28: =(E28-E29)/E29 -> 0.4966443 | I28: =F28-H28 -> -0.53837849 | J28: =F28-G28 -> -0.042970206
... A122: 09/30/2014 | B122: 53.5 | C122: 5460.48 | D122: 2014-09 | E122: 0.02 | F122: =(B122-B123)/B123 -> -0.097655591 | G122: =(C122-C123)/C123 -> -0.011194611 | H122: =(E122-E123)/E123 -> -0.33333333 | I122: =F122-H122 -> 0.23567774 | J122: =F122-G122 -> -0.08646098
A123: 08/29/2014 | B123: 59.29 | C123: 5522.3 | D123: 2014-08 | E123: 0.03

Sheet Charts
A2: date | B2: rolling beta | C2: date | D2: rolling stdev
A3: 08/01/2024 | B3: -2.5968182e-05 | C3: 08/01/2024 | D3: 0.042811239
A4: 07/31/2024 | B4: 3.0981425e-05 | C4: 07/31/2024 | D4: 0.042796735
A5: 07/30/2024 | B5: -3.4219144e-05 | C5: 07/30/2024 | D5: 0.042786676
A6: 07/29/2024 | B6: -3.6759634e-05 | C6: 07/29/2024 | D6: 0.043190381
A7: 07/26/2024 | B7: -2.7248209e-05 | C7: 07/26/2024 | D7: 0.043181611
A8: 07/25/2024 | B8: 1.7645428e-05 | C8: 07/25/2024 | D8: 0.043111768
A9: 07/24/2024 | B9: -5.7387759e-05 | C9: 07/24/2024 | D9: 0.043114172
A10: 07/23/2024 | B10: -8.7889428e-05 | C10: 07/23/2024 | D10: 0.043124417
A11: 07/22/2024 | B11: -2.5535353e-05 | C11: 07/22/2024 | D11: 0.043111663
A12: 07/19/2024 | B12: -3.2260964e-07 | C12: 07/19/2024 | D12: 0.043332429
A13: 07/18/2024 | B13: -5.7420016e-06 | C13: 07/18/2024 | D13: 0.043328489
A14: 07/17/2024 | B14: 4.5103102e-05 | C14: 07/17/2024 | D14: 0.043298018
... A1936: 11/18/2016 | B1936: 0.00056447557 | C1936: 11/18/2016 | D1936: 0.013083319
A1937: 11/17/2016 | C1937: 11/17/2016 | D1937: 0.013257152
A1938: 11/16/2016 | C1938: 11/16/2016 | D1938: 0.013319522
A1939: 11/15/2016 | C1939: 11/15/2016 | D1939: 0.013885242
A1940: 11/14/2016 | C1940: 11/14/2016 | D1940: 0.0138766
A1941: 11/11/2016 | C1941: 11/11/2016 | D1941: 0.013756516
A1942: 11/10/2016 | C1942: 11/10/2016 | D1942: 0.013771246
A1943: 11/09/2016 | C1943: 11/09/2016 | D1943: 0.013768648
A1944: 11/08/2016 | C1944: 11/08/2016 | D1944: 0.013831188
A1945: 11/07/2016 | C1945: 11/07/2016 | D1945: 0.014025312
A1946: 11/04/2016 | C1946: 11/04/2016 | D1946: 0.014005111
A1947: 11/03/2016 | C1947: 11/03/2016 | D1947: 0.013813427
A1948: 11/02/2016 | C1948: 11/02/2016 | D1948: 0.013857068
... A2515: 08/05/2014 | C2515: 08/05/2014 | D2515: 0.016518058
A2516: 08/04/2014 | C2516: 08/04/2014
A2517: 08/01/2014 | C2517: 08/01/2014

Sheet Data
A1: Historical Pricing
A2: Date | B2: Mkt-RF | C2: SMB | D2: HML | E2: RMW | F2: CMA | G2: RF | H2: Closing Price | I2: NAICS | J2: TB | K2: R_PARA | L2: ER_NAICS | M2: R_TB | N2: ER_PARA | O2: ER_NAICS | P2: date | Q2: rolling beta | R2: rolling stdev | T2: beta | U2: =LINEST(N3:N122,O3:O122,FALSE) -> 0.98337135 | V2: stdev | W2: =STDEV(N:N) -> 0.029765281
A3: 08/01/2024 | B3: 1.52 | C3: -0.97 | D3: -1.32 | E3: 0.44 | F3: 1.43 | G3: 0.021 | H3: 11.11 | I3: 5446.68 | J3: 5.12 | K3: =(H3-H4)/H4 -> -0.027145359 | L3: =(I3-I4)/I4 -> -0.01369357 | M3: =(J3-J4)/J4 -> -0.0058252427 | N3: =K3-G3 -> -0.048145359 | O3: =K3-L3 -> -0.013451789 | P3: 08/01/2024 | Q3: =LINEST(N3:N583, B3:B583) -> -2.5968182e-05 | R3: =STDEV(N3:N103) -> 0.042811239 | T3: E(r) | U3: =(5.1+0.852275767*(-0.00049))/100 -> 0.050995824
A4: 07/31/2024 | B4: 1.52 | C4: -0.97 | D4: -1.32 | E4: 0.44 | F4: 1.43 | G4: 0.021 | H4: 11.42 | I4: 5522.3 | J4: 5.15 | K4: =(H4-H5)/H5 -> 0.016014235 | L4: =(I4-I5)/I5 -> 0.015793424 | M4: =(J4-J5)/J5 -> 0.0019455253 | N4: =K4-G4 -> -0.0049857651 | O4: =K4-L4 -> 0.00022081124 | P4: 07/31/2024 | Q4: =LINEST(N4:N584, B4:B584) -> 3.0981425e-05 | R4: =STDEV(N4:N104) -> 0.042796735
A5: 07/30/2024 | B5: -0.5 | C5: 0.69 | D5: 1.37 | E5: 0.46 | F5: -1.03 | G5: 0.021 | H5: 11.24 | I5: 5436.44 | J5: 5.14 | K5: =(H5-H6)/H6 -> 0.016274864 | L5: =(I5-I6)/I6 -> -0.004960154 | M5: =(J5-J6)/J6 -> -0.0019417476 | N5: =K5-G5 -> -0.0047251356 | O5: =K5-L5 -> 0.021235018 | P5: 07/30/2024 | Q5: =LINEST(N5:N585, B5:B585) -> -3.4219144e-05 | R5: =STDEV(N5:N105) -> 0.042786676 | T5: Current Price | U5: =H3 -> 11.11 | W5: =(0.3485-0.2819905) -> 0.0665095
A6: 07/29/2024 | B6: -0.02 | C6: -1.05 | D6: -0.44 | E6: 0.61 | F6: -0.25 | G6: 0.021 | H6: 11.06 | I6: 5463.54 | J6: 5.15 | K6: =(H6-H7)/H7 -> -0.011617516 | L6: =(I6-I7)/I7 -> 0.00081332088 | M6: =(J6-J7)/J7 -> -0.0019379845 | N6: =K6-G6 -> -0.032617516 | O6: =K6-L6 -> -0.012430837 | P6: 07/29/2024 | Q6: =LINEST(N6:N586, B6:B586) -> -3.6759634e-05 | R6: =STDEV(N6:N106) -> 0.043190381 | T6: Exp Price | U6: =U5*(1+U3) -> 11.676564
A7: 07/26/2024 | B7: 1.1 | C7: 0.58 | D7: -0.19 | E7: 0.02 | F7: 0.09 | G7: 0.021 | H7: 11.19 | I7: 5459.1 | J7: 5.16 | K7: =(H7-H8)/H8 -> -0.023560209 | L7: =(I7-I8)/I8 -> 0.011090491 | M7: =(J7-J8)/J8 -> -0.001934236 | N7: =K7-G7 -> -0.044560209 | O7: =K7-L7 -> -0.0346507 | P7: 07/26/2024 | Q7: =LINEST(N7:N587, B7:B587) -> -2.7248209e-05 | R7: =STDEV(N7:N107) -> 0.043181611 | W7: Stage 3
A8: 07/25/2024 | B8: -0.3 | C8: 1.67 | D8: 0.67 | E8: -0.11 | F8: 0.14 | G8: 0.021 | H8: 11.46 | I8: 5399.22 | J8: 5.17 | K8: =(H8-H9)/H9 -> -0.016309013 | L8: =(I8-I9)/I9 -> -0.0051426813 | M8: =(J8-J9)/J9 -> -0.0019305019 | N8: =K8-G8 -> -0.037309013 | O8: =K8-L8 -> -0.011166332 | P8: 07/25/2024 | Q8: =LINEST(N8:N588, B8:B588) -> 1.7645428e-05 | R8: =STDEV(N8:N108) -> 0.043111768 | T8: Trading Str. | U8: short position
A9: 07/24/2024 | B9: -2.4 | C9: 0.02 | D9: 1.72 | E9: 0.1 | F9: 0.08 | G9: 0.021 | H9: 11.65 | I9: 5427.13 | J9: 5.18 | K9: =(H9-H10)/H10 -> -0.0076660988 | L9: =(I9-I10)/I10 -> -0.023149031 | M9: =(J9-J10)/J10 -> 0 | N9: =K9-G9 -> -0.028666099 | O9: =K9-L9 -> 0.015482933 | P9: 07/24/2024 | Q9: =LINEST(N9:N589, B9:B589) -> -5.7387759e-05 | R9: =STDEV(N9:N109) -> 0.043114172 | T9: Sell with min | U9: 11.3 | W9: {=LINEST(N3:N2516, B3:F2516,FALSE)} -> 0.0019167996 | X9: -0.0023848813 | Y9: 0.00048862543 | Z9: -0.00090422124 | AA9: 0.0019177995 | AB9: 0
A10: 07/23/2024 | B10: -0.06 | C10: 1.16 | D10: -0.03 | E10: -0.44 | F10: -0.17 | G10: 0.021 | H10: 11.74 | I10: 5555.74 | J10: 5.18 | K10: =(H10-H11)/H11 -> 0.017331023 | L10: =(I10-I11)/I11 -> -0.0015581167 | M10: =(J10-J11)/J11 -> -0.0019267823 | N10: =K10-G10 -> -0.0036689775 | O10: =K10-L10 -> 0.018889139 | P10: 07/23/2024 | Q10: =LINEST(N10:N590, B10:B590) -> -8.7889428e-05 | R10: =STDEV(N10:N110) -> 0.043124417 | T10: Then buy at | U10: 10.9 | W10: CMA | X10: RMW | Y10: HML | Z10: SMB | AA10: MKT RF | AB10: alpha
A11: 07/22/2024 | B11: 1.08 | C11: 0.52 | D11: -0.53 | E11: -0.36 | F11: 0.69 | G11: 0.021 | H11: 11.54 | I11: 5564.41 | J11: 5.19 | K11: =(H11-H12)/H12 -> 0.0017361111 | L11: =(I11-I12)/I12 -> 0.010792007 | M11: =(J11-J12)/J12 -> -0.0019230769 | N11: =K11-G11 -> -0.019263889 | O11: =K11-L11 -> -0.0090558962 | P11: 07/22/2024 | Q11: =LINEST(N11:N591, B11:B591) -> -2.5535353e-05 | R11: =STDEV(N11:N111) -> 0.043111663
A12: 07/19/2024 | B12: -0.68 | C12: 0.07 | D12: -0.13 | E12: -0.09 | F12: -0.46 | G12: 0.021 | H12: 11.52 | I12: 5505 | J12: 5.2 | K12: =(H12-H13)/H13 -> -0.0094582975 | L12: =(I12-I13)/I13 -> -0.0071402935 | M12: =(J12-J13)/J13 -> -0.0019193858 | N12: =K12-G12 -> -0.030458298 | O12: =K12-L12 -> -0.002318004 | P12: 07/19/2024 | Q12: =LINEST(N12:N592, B12:B592) -> -3.2260964e-07 | R12: =STDEV(N12:N112) -> 0.043332429 | T12: Test Trading Str. | W12: forecasting return | X12: =G3+AA9*B3+Z9*C3+Y9*D3+X9*E3+W9*F3 -> 0.02583884 | Z12: Trading Str.
A13: 07/18/2024 | B13: -0.95 | C13: -1.13 | D13: 0.01 | E13: 0.99 | F13: 0.38 | G13: 0.021 | H13: 11.63 | I13: 5544.59 | J13: 5.21 | K13: =(H13-H14)/H14 -> -0.02021904 | L13: =(I13-I14)/I14 -> -0.0078163725 | M13: =(J13-J14)/J14 -> 0.0019230769 | N13: =K13-G13 -> -0.04121904 | O13: =K13-L13 -> -0.012402667 | P13: 07/18/2024 | Q13: =LINEST(N13:N593, B13:B593) -> -5.7420016e-06 | R13: =STDEV(N13:N113) -> 0.043328489 | T13: Sell | U13: 45506 | W13: current price | X13: =H3 -> 11.11 | Z13: Buy | AA13: Market Order
A14: 07/17/2024 | B14: -1.5 | C14: 0.49 | D14: 2.45 | E14: 0.83 | F14: -0.13 | G14: 0.021 | H14: 11.87 | I14: 5588.27 | J14: 5.2 | K14: =(H14-H15)/H15 -> -0.0066945607 | L14: =(I14-I15)/I15 -> -0.013927513 | M14: =(J14-J15)/J15 -> 0 | N14: =K14-G14 -> -0.027694561 | O14: =K14-L14 -> 0.007232952 | P14: 07/17/2024 | Q14: =LINEST(N14:N594, B14:B594) -> 4.5103102e-05 | R14: =STDEV(N14:N114) -> 0.043298018 | T14: buy | U14: 45506 | W14: expected price | X14: =X13+(1*X12) -> 11.135839 | Z14: Sell | AA14: 11.4
A15: 07/16/2024 | B15: 0.83 | C15: 2.76 | D15: 1.37 | E15: -0.64 | F15: 0.07 | G15: 0.021 | H15: 11.95 | I15: 5667.2 | J15: 5.2 | K15: =(H15-H16)/H16 -> 0.031951641 | L15: =(I15-I16)/I16 -> 0.0063893792 | M15: =(J15-J16)/J16 -> 0 | N15: =K15-G15 -> 0.010951641 | O15: =K15-L15 -> 0.025562262 | P15: 07/16/2024 | Q15: =LINEST(N15:N595, B15:B595) -> 2.6406829e-05 | R15: =STDEV(N15:N115) -> 0.043294333
A16: 07/15/2024 | B16: 0.38 | C16: 1.17 | D16: 0.58 | E16: -0.21 | F16: -0.35 | G16: 0.021 | H16: 11.58 | I16: 5631.22 | J16: 5.2 | K16: =(H16-H17)/H17 -> 0.0017301038 | L16: =(I16-I17)/I17 -> 0.0028261818 | M16: =(J16-J17)/J17 -> -0.0019193858 | N16: =K16-G16 -> -0.019269896 | O16: =K16-L16 -> -0.001096078 | P16: 07/15/2024 | Q16: =LINEST(N16:N596, B16:B596) -> 3.5465665e-05 | R16: =STDEV(N16:N116) -> 0.043438949 | T16: return | U16: =(U9-U10)/U10 -> 0.036697248
A17: 07/12/2024 | B17: 0.59 | C17: 0.61 | D17: -0.45 | E17: -0.49 | F17: 0.14 | G17: 0.021 | H17: 11.56 | I17: 5615.35 | J17: 5.21 | K17: =(H17-H18)/H18 -> -0.014492754 | L17: =(I17-I18)/I18 -> 0.0055170166 | M17: =(J17-J18)/J18 -> 0 | N17: =K17-G17 -> -0.035492754 | O17: =K17-L17 -> -0.02000977 | P17: 07/12/2024 | Q17: =LINEST(N17:N597, B17:B597) -> 2.7592697e-05 | R17: =STDEV(N17:N117) -> 0.043674816
A18: 07/11/2024 | B18: -0.6 | C18: 4.21 | D18: 1.76 | E18: -1.09 | F18: -0.09 | G18: 0.021 | H18: 11.73 | I18: 5584.54 | J18: 5.21 | K18: =(H18-H19)/H19 -> 0.0025641026 | L18: =(I18-I19)/I19 -> -0.0087630083 | M18: =(J18-J19)/J19 -> -0.0038240918 | N18: =K18-G18 -> -0.018435897 | O18: =K18-L18 -> 0.011327111 | P18: 07/11/2024 | Q18: =LINEST(N18:N598, B18:B598) -> 0.00011912305 | R18: =STDEV(N18:N118) -> 0.043676636
A19: 07/10/2024 | B19: 0.97 | C19: -0.13 | D19: 0.43 | E19: 0.16 | F19: 0.22 | G19: 0.021 | H19: 11.7 | I19: 5633.91 | J19: 5.23 | K19: =(H19-H20)/H20 -> 0.014744146 | L19: =(I19-I20)/I20 -> 0.010208034 | M19: =(J19-J20)/J20 -> 0 | N19: =K19-G19 -> -0.0062558543 | O19: =K19-L19 -> 0.004536112 | P19: 07/10/2024 | Q19: =LINEST(N19:N599, B19:B599) -> 0.00011929339 | R19: =STDEV(N19:N119) -> 0.043781012
A20: 07/09/2024 | B20: 0 | C20: -0.58 | D20: 0.48 | E20: -0.44 | F20: 0.67 | G20: 0.021 | H20: 11.53 | I20: 5576.98 | J20: 5.23 | K20: =(H20-H21)/H21 -> 0.031305903 | L20: =(I20-I21)/I21 -> 0.00074109298 | M20: =(J20-J21)/J21 -> 0 | N20: =K20-G20 -> 0.010305903 | O20: =K20-L20 -> 0.03056481 | P20: 07/09/2024 | Q20: =LINEST(N20:N600, B20:B600) -> 0.0004807075 | R20: =STDEV(N20:N120) -> 0.04393596
A21: 07/08/2024 | B21: 0.1 | C21: 0.54 | D21: -0.22 | E21: -0.34 | F21: 0.46 | G21: 0.021 | H21: 11.18 | I21: 5572.85 | J21: 5.23 | K21: =(H21-H22)/H22 -> -0.053344623 | L21: =(I21-I22)/I22 -> 0.0010166709 | M21: =(J21-J22)/J22 -> 0 | N21: =K21-G21 -> -0.074344623 | O21: =K21-L21 -> -0.054361294 | P21: 07/08/2024 | Q21: =LINEST(N21:N601, B21:B601) -> 0.00047448271 | R21: =STDEV(N21:N121) -> 0.043829292
A22: 07/05/2024 | B22: 0.48 | C22: -0.79 | D22: -1.42 | E22: -0.32 | F22: -1.02 | G22: 0.021 | H22: 11.81 | I22: 5567.19 | J22: 5.23 | K22: =(H22-H23)/H23 -> 0.030541012 | L22: =(I22-I23)/I23 -> 0.0054487793 | M22: =(J22-J23)/J23 -> 0.046 | N22: =K22-G22 -> 0.0095410122 | O22: =K22-L22 -> 0.025092233 | P22: 07/05/2024 | Q22: =LINEST(N22:N602, B22:B602) -> 0.00047600709 | R22: =STDEV(N22:N122) -> 0.043524566
A23: 07/03/2024 | B23: 0.48 | C23: -0.3 | D23: -0.68 | E23: -0.04 | F23: 0.58 | G23: 0.021 | H23: 11.46 | I23: 5537.02 | J23: 5 | K23: =(H23-H24)/H24 -> 0.069029851 | L23: =(I23-I24)/I24 -> 0.0050843981 | M23: =(J23-J24)/J24 -> -0.045801527 | N23: =K23-G23 -> 0.048029851 | O23: =K23-L23 -> 0.063945453 | P23: 07/03/2024 | Q23: =LINEST(N23:N603, B23:B603) -> 0.00042859259 | R23: =STDEV(N23:N123) -> 0.044164007
A24: 07/02/2024 | B24: 0.58 | C24: -0.47 | D24: 0.39 | E24: 0.51 | F24: -0.64 | G24: 0.021 | H24: 10.72 | I24: 5509.01 | J24: 5.24 | K24: =(H24-H25)/H25 -> 0.057199211 | L24: =(I24-I25)/I25 -> 0.0061953319 | M24: =(J24-J25)/J25 -> 0 | N24: =K24-G24 -> 0.036199211 | O24: =K24-L24 -> 0.051003879 | P24: 07/02/2024 | Q24: =LINEST(N24:N604, B24:B604) -> 0.00037705171 | R24: =STDEV(N24:N124) -> 0.043599619
A25: 07/01/2024 | B25: 0.22 | C25: -1.06 | D25: -0.46 | E25: 0.49 | F25: -0.32 | G25: 0.021 | H25: 10.14 | I25: 5475.09 | J25: 5.24 | K25: =(H25-H26)/H26 -> -0.024061598 | L25: =(I25-I26)/I26 -> 0.002675589 | M25: =(J25-J26)/J26 -> 0 | N25: =K25-G25 -> -0.045061598 | O25: =K25-L25 -> -0.026737187 | P25: 07/01/2024 | Q25: =LINEST(N25:N605, B25:B605) -> 0.00033903407 | R25: =STDEV(N25:N125) -> 0.043273952
A26: 06/28/2024 | B26: -0.35 | C26: 1 | D26: 1.28 | E26: -0.19 | F26: 0.72 | G26: 0.022 | H26: 10.39 | I26: 5460.48 | J26: 5.24 | K26: =(H26-H27)/H27 -> 0.012670565 | L26: =(I26-I27)/I27 -> -0.0040836277 | M26: =(J26-J27)/J27 -> 0.0038314176 | N26: =K26-G26 -> -0.0093294347 | O26: =K26-L26 -> 0.016754193 | P26: 06/28/2024 | Q26: =LINEST(N26:N606, B26:B606) -> 0.00036095907 | R26: =STDEV(N26:N126) -> 0.043244651
A27: 06/27/2024 | B27: 0.14 | C27: 0.53 | D27: -0.39 | E27: -0.97 | F27: -0.12 | G27: 0.022 | H27: 10.26 | I27: 5482.87 | J27: 5.22 | K27: =(H27-H28)/H28 -> 0.029087262 | L27: =(I27-I28)/I28 -> 0.00090728199 | M27: =(J27-J28)/J28 -> -0.0019120459 | N27: =K27-G27 -> 0.0070872618 | O27: =K27-L27 -> 0.02817998 | P27: 06/27/2024 | Q27: =LINEST(N27:N607, B27:B607) -> 0.00027231793 | R27: =STDEV(N27:N127) -> 0.043230104
A28: 06/26/2024 | B28: 0.16 | C28: -0.01 | D28: -0.19 | E28: 0.46 | F28: -0.26 | G28: 0.022 | H28: 9.97 | I28: 5477.9 | J28: 5.23 | K28: =(H28-H29)/H29 -> -0.013847676 | L28: =(I28-I29)/I29 -> 0.0015724133 | M28: =(J28-J29)/J29 -> -0.0019083969 | N28: =K28-G28 -> -0.035847676 | O28: =K28-L28 -> -0.015420089 | P28: 06/26/2024 | Q28: =LINEST(N28:N608, B28:B608) -> 0.00011502254 | R28: =STDEV(N28:N128) -> 0.043669303
... A1936: 11/18/2016 | B1936: 0.31 | C1936: 0.64 | D1936: 0.53 | E1936: 0.85 | F1936: 0.28 | G1936: 0.001 | H1936: 60 | I1936: 2202.94 | J1936: 0.73 | K1936: =(H1936-H1937)/H1937 -> -0.0011653071 | L1936: =(I1936-I1937)/I1937 -> 0.0021654278 | M1936: =(J1936-J1937)/J1937 -> 0.042857143 | N1936: =K1936-G1936 -> -0.0021653071 | O1936: =K1936-L1936 -> -0.0033307349 | P1936: 11/18/2016 | Q1936: =LINEST(N1936:N2516, B1936:B2516) -> 0.00056447557 | R1936: =STDEV(N1936:N2036) -> 0.013083319
A1937: 11/17/2016 | B1937: 0.77 | C1937: -0.26 | D1937: 0.06 | E1937: -0.05 | F1937: 0.35 | G1937: 0.001 | H1937: 60.07 | I1937: 2198.18 | J1937: 0.7 | K1937: =(H1937-H1938)/H1938 -> 0.011620074 | L1937: =(I1937-I1938)/I1938 -> 0.0074613869 | M1937: =(J1937-J1938)/J1938 -> 0.060606061 | N1937: =K1937-G1937 -> 0.010620074 | O1937: =K1937-L1937 -> 0.0041586872 | P1937: 11/17/2016 | R1937: =STDEV(N1937:N2037) -> 0.013257152
A1938: 11/16/2016 | B1938: -0.16 | C1938: 0.57 | D1938: 0.38 | E1938: -0.2 | F1938: 0.11 | G1938: 0.001 | H1938: 59.38 | I1938: 2181.9 | J1938: 0.66 | K1938: =(H1938-H1939)/H1939 -> 0.0028711366 | L1938: =(I1938-I1939)/I1939 -> -0.0023867003 | M1938: =(J1938-J1939)/J1939 -> 0.064516129 | N1938: =K1938-G1938 -> 0.0018711366 | O1938: =K1938-L1938 -> 0.005257837 | P1938: 11/16/2016 | R1938: =STDEV(N1938:N2038) -> 0.013319522
A1939: 11/15/2016 | B1939: 0.56 | C1939: 0.16 | D1939: -0.15 | E1939: 0.16 | F1939: -0.42 | G1939: 0.001 | H1939: 59.21 | I1939: 2187.12 | J1939: 0.62 | K1939: =(H1939-H1940)/H1940 -> 0.0059463133 | L1939: =(I1939-I1940)/I1940 -> 0.0046762887 | M1939: =(J1939-J1940)/J1940 -> 0.16981132 | N1939: =K1939-G1939 -> 0.0049463133 | O1939: =K1939-L1939 -> 0.0012700246 | P1939: 11/15/2016 | R1939: =STDEV(N1939:N2039) -> 0.013885242
A1940: 11/14/2016 | B1940: -0.12 | C1940: 0.22 | D1940: -0.56 | E1940: 0.76 | F1940: -0.16 | G1940: 0.001 | H1940: 58.86 | I1940: 2176.94 | J1940: 0.53 | K1940: =(H1940-H1941)/H1941 -> 0.019397298 | L1940: =(I1940-I1941)/I1941 -> -0.0015822857 | M1940: =(J1940-J1941)/J1941 -> 0.06 | N1940: =K1940-G1940 -> 0.018397298 | O1940: =K1940-L1940 -> 0.020979584 | P1940: 11/14/2016 | R1940: =STDEV(N1940:N2040) -> 0.0138766
A1941: 11/11/2016 | B1941: 0.8 | C1941: -0.54 | D1941: 0.15 | E1941: -0.5 | F1941: 0.22 | G1941: 0.001 | H1941: 57.74 | I1941: 2180.39 | J1941: 0.5 | K1941: =(H1941-H1942)/H1942 -> 0.01032371 | L1941: =(I1941-I1942)/I1942 -> 0.0074808243 | M1941: =(J1941-J1942)/J1942 -> -0.019607843 | N1941: =K1941-G1941 -> 0.0093237095 | O1941: =K1941-L1941 -> 0.0028428852 | P1941: 11/11/2016 | R1941: =STDEV(N1941:N2041) -> 0.013756516
A1942: 11/10/2016 | B1942: 0.21 | C1942: 0.92 | D1942: 1.41 | E1942: -0.22 | F1942: 0.34 | G1942: 0.001 | H1942: 57.15 | I1942: 2164.2 | J1942: 0.51 | K1942: =(H1942-H1943)/H1943 -> -0.0047021944 | L1942: =(I1942-I1943)/I1943 -> -0.00011550278 | M1942: =(J1942-J1943)/J1943 -> 0 | N1942: =K1942-G1942 -> -0.0057021944 | O1942: =K1942-L1942 -> -0.0045866916 | P1942: 11/10/2016 | R1942: =STDEV(N1942:N2042) -> 0.013771246
A1943: 11/09/2016 | B1943: 0.18 | C1943: 2.53 | D1943: -0.02 | E1943: 0.02 | F1943: -0.33 | G1943: 0.001 | H1943: 57.42 | I1943: 2164.45 | J1943: 0.51 | K1943: =(H1943-H1944)/H1944 -> -0.005369825 | L1943: =(I1943-I1944)/I1944 -> -0.0013979368 | M1943: =(J1943-J1944)/J1944 -> -0.019230769 | N1943: =K1943-G1943 -> -0.006369825 | O1943: =K1943-L1943 -> -0.0039718883 | P1943: 11/09/2016 | R1943: =STDEV(N1943:N2043) -> 0.013768648
A1944: 11/08/2016 | B1944: 0.32 | C1944: 1.46 | D1944: 1.84 | E1944: -0.26 | F1944: 0.35 | G1944: 0.001 | H1944: 57.73 | I1944: 2167.48 | J1944: 0.52 | K1944: =(H1944-H1945)/H1945 -> 0.0019090594 | L1944: =(I1944-I1945)/I1945 -> 0.0019507595 | M1944: =(J1944-J1945)/J1945 -> -0.018867925 | N1944: =K1944-G1944 -> 0.00090905935 | O1944: =K1944-L1944 -> -4.1700147e-05 | P1944: 11/08/2016 | R1944: =STDEV(N1944:N2044) -> 0.013831188
A1945: 11/07/2016 | B1945: 1.46 | C1945: 2.13 | D1945: 1.07 | E1945: -0.81 | F1945: 0.71 | G1945: 0.001 | H1945: 57.62 | I1945: 2163.26 | J1945: 0.53 | K1945: =(H1945-H1946)/H1946 -> 0.010699877 | L1945: =(I1945-I1946)/I1946 -> 0.011077044 | M1945: =(J1945-J1946)/J1946 -> -0.894 | N1945: =K1945-G1945 -> 0.0096998772 | O1945: =K1945-L1945 -> -0.00037716666 | P1945: 11/07/2016 | R1945: =STDEV(N1945:N2045) -> 0.014025312
A1946: 11/04/2016 | B1946: 0.4 | C1946: -0.11 | D1946: -0.22 | E1946: -0.06 | F1946: 0.29 | G1946: 0.001 | H1946: 57.01 | I1946: 2139.56 | J1946: 5 | K1946: =(H1946-H1947)/H1947 -> 0.027207207 | L1946: =(I1946-I1947)/I1947 -> 0.0037719562 | M1946: =(J1946-J1947)/J1947 -> 8.6153846 | N1946: =K1946-G1946 -> 0.026207207 | O1946: =K1946-L1946 -> 0.023435251 | P1946: 11/04/2016 | R1946: =STDEV(N1946:N2046) -> 0.014005111
A1947: 11/03/2016 | B1947: 2.23 | C1947: 0.17 | D1947: -0.13 | E1947: -0.31 | F1947: -0.22 | G1947: 0.001 | H1947: 55.5 | I1947: 2131.52 | J1947: 0.52 | K1947: =(H1947-H1948)/H1948 -> 0.0063463282 | L1947: =(I1947-I1948)/I1948 -> 0.022223501 | M1947: =(J1947-J1948)/J1948 -> 0 | N1947: =K1947-G1947 -> 0.0053463282 | O1947: =K1947-L1947 -> -0.015877173 | P1947: 11/03/2016 | R1947: =STDEV(N1947:N2047) -> 0.013813427
...

Sheet Price Chart
A2: Date | B2: Closing Price
A3: 08/01/2024 | B3: 11.11
A4: 07/31/2024 | B4: 11.42
A5: 07/30/2024 | B5: 11.24
A6: 07/29/2024 | B6: 11.06
A7: 07/26/2024 | B7: 11.19
A8: 07/25/2024 | B8: 11.46
A9: 07/24/2024 | B9: 11.65
A10: 07/23/2024 | B10: 11.74
A11: 07/22/2024 | B11: 11.54
A12: 07/19/2024 | B12: 11.52
A13: 07/18/2024 | B13: 11.63
A14: 07/17/2024 | B14: 11.87
... A2517: 08/01/2014 | B2517: 57.03

Sheet Stock Prices
A2: Date | B2: Paramount | C2: Comcast | D2: LuluLemon | E2: Hyatt Hotels | F2: MGM Resorts | G2: Ford Motors | H2: Mkt-RF | I2: SMB | J2: HML | K2: RF | L2: ER_PARA | M2: ER_COM | N2: ER_LULU | O2: ER_HYATT | P2: ER_MGM | Q2: ER_FORD
A3: average
A4: 08/01/2024 | B4: 11.11 | C4: =_xlfn.XLOOKUP(A4, [1]report!$A$8:$A$2523, [1]report!$E$8:$E$2523, "n/A", 0) -> 40.26 | D4: =_xlfn.XLOOKUP(A4, [2]report!$A$8:$A$2521, [2]report!$E$8:$E$2521, "n/A", 0) -> 249.05 | E4: =_xlfn.XLOOKUP(A4, [3]report!$A$12:$A$2526, [3]report!$E$12:$E$2526, "n/A", 0) -> 141.16 | F4: =_xlfn.XLOOKUP(A4, [4]report!$A$12:$A$2526, [4]report!$E$12:$E$2526, "n/A",0) -> 37.29 | G4: =_xlfn.XLOOKUP(A4, [5]report!$A$12:$A$2526, [5]report!$E$12:$E$2526, "n/A",0) -> 10.69 | H4: 1.52 | I4: -0.97 | J4: -1.32 | K4: 0.021 | L4: =(B4-B5)/B5 -> -0.027145359 | M4: =(C4-C5)/C5 -> -0.024472983 | N4: =(D4-D5)/D5 -> -0.037153019 | O4: =(E4-E5)/E5 -> -0.041878776 | P4: =(F4-F5)/F5 -> -0.13218525 | Q4: =(G4-G5)/G5 -> -0.012014787
A5: 07/31/2024 | B5: 11.42 | C5: =_xlfn.XLOOKUP(A5, [1]report!$A$8:$A$2523, [1]report!$E$8:$E$2523, "n/A", 0) -> 41.27 | D5: =_xlfn.XLOOKUP(A5, [2]report!$A$8:$A$2521, [2]report!$E$8:$E$2521, "n/A", 0) -> 258.66 | E5: =_xlfn.XLOOKUP(A5, [3]report!$A$12:$A$2526, [3]report!$E$12:$E$2526, "n/A", 0) -> 147.33 | F5: =_xlfn.XLOOKUP(A5, [4]report!$A$12:$A$2526, [4]report!$E$12:$E$2526, "n/A",0) -> 42.97 | G5: =_xlfn.XLOOKUP(A5, [5]report!$A$12:$A$2526, [5]report!$E$12:$E$2526, "n/A",0) -> 10.82 | H5: 1.52 | I5: -0.97 | J5: -1.32 | K5: 0.021 | L5: =(B5-B6)/B6 -> 0.016014235 | M5: =(C5-C6)/C6 -> 0.011271747 | N5: =(D5-D6)/D6 -> 0.010390625 | O5: =(E5-E6)/E6 -> -0.026882431 | P5: =(F5-F6)/F6 -> 0.0044413277 | Q5: =(G5-G6)/G6 -> -0.0018450185
A6: 07/30/2024 | B6: 11.24 | C6: =_xlfn.XLOOKUP(A6, [1]report!$A$8:$A$2523, [1]report!$E$8:$E$2523, "n/A", 0) -> 40.81 | D6: =_xlfn.XLOOKUP(A6, [2]report!$A$8:$A$2521, [2]report!$E$8:$E$2521, "n/A", 0) -> 256 | E6: =_xlfn.XLOOKUP(A6, [3]report!$A$12:$A$2526, [3]report!$E$12:$E$2526, "n/A", 0) -> 151.4 | F6: =_xlfn.XLOOKUP(A6, [4]report!$A$12:$A$2526, [4]report!$E$12:$E$2526, "n/A",0) -> 42.78 | G6: =_xlfn.XLOOKUP(A6, [5]report!$A$12:$A$2526, [5]report!$E$12:$E$2526, "n/A",0) -> 10.84 | H6: -0.5 | I6: 0.69 | J6: 1.37 | K6: 0.021 | L6: =(B6-B7)/B7 -> 0.016274864 | M6: =(C6-C7)/C7 -> 0.0031956735 | N6: =(D6-D7)/D7 -> -0.011697487 | O6: =(E6-E7)/E7 -> 0.0043783999 | P6: =(F6-F7)/F7 -> 0 | Q6: =(G6-G7)/G7 -> -0.015440509
A7: 07/29/2024 | B7: 11.06 | C7: =_xlfn.XLOOKUP(A7, [1]report!$A$8:$A$2523, [1]report!$E$8:$E$2523, "n/A", 0) -> 40.68 | D7: =_xlfn.XLOOKUP(A7, [2]report!$A$8:$A$2521, [2]report!$E$8:$E$2521, "n/A", 0) -> 259.03 | E7: =_xlfn.XLOOKUP(A7, [3]report!$A$12:$A$2526, [3]report!$E$12:$E$2526, "n/A", 0) -> 150.74 | F7: =_xlfn.XLOOKUP(A7, [4]report!$A$12:$A$2526, [4]report!$E$12:$E$2526, "n/A",0) -> 42.78 | G7: =_xlfn.XLOOKUP(A7, [5]report!$A$12:$A$2526, [5]report!$E$12:$E$2526, "n/A",0) -> 11.01 | H7: -0.02 | I7: -1.05 | J7: -0.44 | K7: 0.021 | L7: =(B7-B8)/B8 -> -0.011617516 | M7: =(C7-C8)/C8 -> 0.024943311 | N7: =(D7-D8)/D8 -> 0.021814596 | O7: =(E7-E8)/E8 -> 0.0059392726 | P7: =(F7-F8)/F8 -> 0.022466539 | Q7: =(G7-G8)/G8 -> -0.016085791
A8: 07/26/2024 | B8: 11.19 | C8: =_xlfn.XLOOKUP(A8, [1]report!$A$8:$A$2523, [1]report!$E$8:$E$2523, "n/A", 0) -> 39.69 | D8: =_xlfn.XLOOKUP(A8, [2]report!$A$8:$A$2521, [2]report!$E$8:$E$2521, "n/A", 0) -> 253.5 | E8: =_xlfn.XLOOKUP(A8, [3]report!$A$12:$A$2526, [3]report!$E$12:$E$2526, "n/A", 0) -> 149.85 | F8: =_xlfn.XLOOKUP(A8, [4]report!$A$12:$A$2526, [4]report!$E$12:$E$2526, "n/A",0) -> 41.84 | G8: =_xlfn.XLOOKUP(A8, [5]report!$A$12:$A$2526, [5]report!$E$12:$E$2526, "n/A",0) -> 11.19 | H8: 1.1 | I8: 0.58 | J8: -0.19 | K8: 0.021 | L8: =(B8-B9)/B9 -> -0.023560209 | M8: =(C8-C9)/C9 -> 0.03791841 | N8: =(D8-D9)/D9 -> 0.02498787 | O8: =(E8-E9)/E9 -> -0.0027286038 | P8: =(F8-F9)/F9 -> 0.0096525097 | Q8: =(G8-G9)/G9 -> 0.002688172
A9: 07/25/2024 | B9: 11.46 | C9: =_xlfn.XLOOKUP(A9, [1]report!$A$8:$A$2523, [1]report!$E$8:$E$2523, "n/A", 0) -> 38.24 | D9: =_xlfn.XLOOKUP(A9, [2]report!$A$8:$A$2521, [2]report!$E$8:$E$2521, "n/A", 0) -> 247.32 | E9: =_xlfn.XLOOKUP(A9, [3]report!$A$12:$A$2526, [3]report!$E$12:$E$2526, "n/A", 0) -> 150.26 | F9: =_xlfn.XLOOKUP(A9, [4]report!$A$12:$A$2526, [4]report!$E$12:$E$2526, "n/A",0) -> 41.44 | G9: =_xlfn.XLOOKUP(A9, [5]report!$A$12:$A$2526, [5]report!$E$12:$E$2526, "n/A",0) -> 11.16 | H9: -0.3 | I9: 1.67 | J9: 0.67 | K9: 0.021 | L9: =(B9-B10)/B10 -> -0.016309013 | M9: =(C9-C10)/C10 -> 0.0039380415 | N9: =(D9-D10)/D10 -> -0.090935823 | O9: =(E9-E10)/E10 -> -0.00033264587 | P9: =(F9-F10)/F10 -> -0.023562677 | Q9: =(G9-G10)/G10 -> -0.18361375
A10: 07/24/2024 | B10: 11.65 | C10: =_xlfn.XLOOKUP(A10, [1]report!$A$8:$A$2523, [1]report!$E$8:$E$2523, "n/A", 0) -> 38.09 | D10: =_xlfn.XLOOKUP(A10, [2]report!$A$8:$A$2521, [2]report!$E$8:$E$2521, "n/A", 0) -> 272.06 | E10: =_xlfn.XLOOKUP(A10, [3]report!$A$12:$A$2526, [3]report!$E$12:$E$2526, "n/A", 0) -> 150.31 | F10: =_xlfn.XLOOKUP(A10, [4]report!$A$12:$A$2526, [4]report!$E$12:$E$2526, "n/A",0) -> 42.44 | G10: =_xlfn.XLOOKUP(A10, [5]report!$A$12:$A$2526, [5]report!$E$12:$E$2526, "n/A",0) -> 13.67 | H10: -2.4 | I10: 0.02 | J10: 1.72 | K10: 0.021 | L10: =(B10-B11)/B11 -> -0.0076660988 | M10: =(C10-C11)/C11 -> -0.010906258 | N10: =(D10-D11)/D11 -> -0.033088105 | O10: =(E10-E11)/E11 -> -0.030695815 | P10: =(F10-F11)/F11 -> -0.030607583 | Q10: =(G10-G11)/G11 -> -0.011569053
A11: 07/23/2024 | B11: 11.74 | C11: =_xlfn.XLOOKUP(A11, [1]report!$A$8:$A$2523, [1]report!$E$8:$E$2523, "n/A", 0) -> 38.51 | D11: =_xlfn.XLOOKUP(A11, [2]report!$A$8:$A$2521, [2]report!$E$8:$E$2521, "n/A", 0) -> 281.37 | E11: =_xlfn.XLOOKUP(A11, [3]report!$A$12:$A$2526, [3]report!$E$12:$E$2526, "n/A", 0) -> 155.07 | F11: =_xlfn.XLOOKUP(A11, [4]report!$A$12:$A$2526, [4]report!$E$12:$E$2526, "n/A",0) -> 43.78 | G11: =_xlfn.XLOOKUP(A11, [5]report!$A$12:$A$2526, [5]report!$E$12:$E$2526, "n/A",0) -> 13.83 | H11: -0.06 | I11: 1.16 | J11: -0.03 | K11: 0.021 | L11: =(B11-B12)/B12 -> 0.017331023 | M11: =(C11-C12)/C12 -> -0.025803187 | N11: =(D11-D12)/D12 -> -0.012736842 | O11: =(E11-E12)/E12 -> 0.0071442489 | P11: =(F11-F12)/F12 -> 0.00022846699 | Q11: =(G11-G12)/G12 -> -0.020538244
A12: 07/22/2024 | B12: 11.54 | C12: =_xlfn.XLOOKUP(A12, [1]report!$A$8:$A$2523, [1]report!$E$8:$E$2523, "n/A", 0) -> 39.53 | D12: =_xlfn.XLOOKUP(A12, [2]report!$A$8:$A$2521, [2]report!$E$8:$E$2521, "n/A", 0) -> 285 | E12: =_xlfn.XLOOKUP(A12, [3]report!$A$12:$A$2526, [3]report!$E$12:$E$2526, "n/A", 0) -> 153.97 | F12: =_xlfn.XLOOKUP(A12, [4]report!$A$12:$A$2526, [4]report!$E$12:$E$2526, "n/A",0) -> 43.77 | G12: =_xlfn.XLOOKUP(A12, [5]report!$A$12:$A$2526, [5]report!$E$12:$E$2526, "n/A",0) -> 14.12 | H12: 1.08 | I12: 0.52 | J12: -0.53 | K12: 0.021 | L12: =(B12-B13)/B13 -> 0.0017361111 | M12: =(C12-C13)/C13 -> -0.013722555 | N12: =(D12-D13)/D13 -> 0.017003586 | O12: =(E12-E13)/E13 -> -0.0041394476 | P12: =(F12-F13)/F13 -> -0.035265594 | Q12: =(G12-G13)/G13 -> 0.010014306
A13: 07/19/2024 | B13: 11.52 | C13: =_xlfn.XLOOKUP(A13, [1]report!$A$8:$A$2523, [1]report!$E$8:$E$2523, "n/A", 0) -> 40.08 | D13: =_xlfn.XLOOKUP(A13, [2]report!$A$8:$A$2521, [2]report!$E$8:$E$2521, "n/A", 0) -> 280.235 | E13: =_xlfn.XLOOKUP(A13, [3]report!$A$12:$A$2526, [3]report!$E$12:$E$2526, "n/A", 0) -> 154.61 | F13: =_xlfn.XLOOKUP(A13, [4]report!$A$12:$A$2526, [4]report!$E$12:$E$2526, "n/A",0) -> 45.37 | G13: =_xlfn.XLOOKUP(A13, [5]report!$A$12:$A$2526, [5]report!$E$12:$E$2526, "n/A",0) -> 13.98 | H13: -0.68 | I13: 0.07 | J13: -0.13 | K13: 0.021 | L13: =(B13-B14)/B14 -> -0.0094582975 | M13: =(C13-C14)/C14 -> -0.0014947683 | N13: =(D13-D14)/D14 -> -0.017167608 | O13: =(E13-E14)/E14 -> 0.010919315 | P13: =(F13-F14)/F14 -> 0.0015452539 | Q13: =(G13-G14)/G14 -> -0.039175258
A14: 07/18/2024 | B14: 11.63 | C14: =_xlfn.XLOOKUP(A14, [1]report!$A$8:$A$2523, [1]report!$E$8:$E$2523, "n/A", 0) -> 40.14 | D14: =_xlfn.XLOOKUP(A14, [2]report!$A$8:$A$2521, [2]report!$E$8:$E$2521, "n/A", 0) -> 285.13 | E14: =_xlfn.XLOOKUP(A14, [3]report!$A$12:$A$2526, [3]report!$E$12:$E$2526, "n/A", 0) -> 152.94 | F14: =_xlfn.XLOOKUP(A14, [4]report!$A$12:$A$2526, [4]report!$E$12:$E$2526, "n/A",0) -> 45.3 | G14: =_xlfn.XLOOKUP(A14, [5]report!$A$12:$A$2526, [5]report!$E$12:$E$2526, "n/A",0) -> 14.55 | H14: -0.95 | I14: -1.13 | J14: 0.01 | K14: 0.021 | L14: =(B14-B15)/B15 -> -0.02021904 | M14: =(C14-C15)/C15 -> -0.011086475 | N14: =(D14-D15)/D15 -> -0.025796091 | O14: =(E14-E15)/E15 -> -0.026789691 | P14: =(F14-F15)/F15 -> -0.01926824 | Q14: =(G14-G15)/G15 -> 0.0048342541
A15: 07/17/2024 | B15: 11.87 | C15: =_xlfn.XLOOKUP(A15, [1]report!$A$8:$A$2523, [1]report!$E$8:$E$2523, "n/A", 0) -> 40.59 | D15: =_xlfn.XLOOKUP(A15, [2]report!$A$8:$A$2521, [2]report!$E$8:$E$2521, "n/A", 0) -> 292.68 | E15: =_xlfn.XLOOKUP(A15, [3]report!$A$12:$A$2526, [3]report!$E$12:$E$2526, "n/A", 0) -> 157.15 | F15: =_xlfn.XLOOKUP(A15, [4]report!$A$12:$A$2526, [4]report!$E$12:$E$2526, "n/A",0) -> 46.19 | G15: =_xlfn.XLOOKUP(A15, [5]report!$A$12:$A$2526, [5]report!$E$12:$E$2526, "n/A",0) -> 14.48 | H15: -1.5 | I15: 0.49 | J15: 2.45 | K15: 0.021 | L15: =(B15-B16)/B16 -> -0.0066945607 | M15: =(C15-C16)/C16 -> 0.024741227 | N15: =(D15-D16)/D16 -> 0.0031532767 | O15: =(E15-E16)/E16 -> -0.031253853 | P15: =(F15-F16)/F16 -> -0.012612227 | Q15: =(G15-G16)/G16 -> 0.0062543433
... A560: 05/11/2022 | B560: 26.69 | C560: =_xlfn.XLOOKUP(A560, [1]report!$A$8:$A$2523, [1]report!$E$8:$E$2523, "n/A", 0) -> 39.84 | D560: =_xlfn.XLOOKUP(A560, [2]report!$A$8:$A$2521, [2]report!$E$8:$E$2521, "n/A", 0) -> 291.3 | E560: =_xlfn.XLOOKUP(A560, [3]report!$A$12:$A$2526, [3]report!$E$12:$E$2526, "n/A", 0) -> 83.34 | F560: =_xlfn.XLOOKUP(A560, [4]report!$A$12:$A$2526, [4]report!$E$12:$E$2526, "n/A",0) -> 35.07 | G560: =_xlfn.XLOOKUP(A560, [5]report!$A$12:$A$2526, [5]report!$E$12:$E$2526, "n/A",0) -> 12.83 | H560: 2.76 | I560: 0.37 | J560: -2.16 | K560: 0.001 | L560: =(B560-B561)/B561 -> -0.026622903 | M560: =(C560-C561)/C561 -> -0.011414392 | N560: =(D560-D561)/D561 -> 0 | O560: =(E560-E561)/E561 -> 0 | P560: =(F560-F561)/F561 -> 0 | Q560: =(G560-G561)/G561 -> 0
A561: 05/10/2022 | B561: 27.42 | C561: =_xlfn.XLOOKUP(A561, [1]report!$A$8:$A$2523, [1]report!$E$8:$E$2523, "n/A", 0) -> 40.3 | D561: 291.3 | E561: 83.34 | F561: 35.07 | G561: 12.83 | H561: 0.17 | I561: 1.21 | J561: -1.24 | K561: 0.001 | L561: =(B561-B562)/B562 -> -0.00072886297 | M561: =(C561-C562)/C562 -> 0.013581489 | N561: =(D561-D562)/D562 -> -0.0047150472 | O561: =(E561-E562)/E562 -> 0.044491791 | P561: =(F561-F562)/F562 -> -0.0019920319 | Q561: =(G561-G562)/G562 -> -0.04038893
A562: 05/09/2022 | B562: 27.44 | C562: =_xlfn.XLOOKUP(A562, [1]report!$A$8:$A$2523, [1]report!$E$8:$E$2523, "n/A", 0) -> 39.76 | D562: =_xlfn.XLOOKUP(A562, [2]report!$A$8:$A$2521, [2]report!$E$8:$E$2521, "n/A", 0) -> 292.68 | E562: =_xlfn.XLOOKUP(A562, [3]report!$A$12:$A$2526, [3]report!$E$12:$E$2526, "n/A", 0) -> 79.79 | F562: =_xlfn.XLOOKUP(A562, [4]report!$A$12:$A$2526, [4]report!$E$12:$E$2526, "n/A",0) -> 35.14 | G562: =_xlfn.XLOOKUP(A562, [5]report!$A$12:$A$2526, [5]report!$E$12:$E$2526, "n/A",0) -> 13.37 | H562: -1.95 | I562: -0.59 | J562: 2.59 | K562: 0.001 | L562: =(B562-B563)/B563 -> -0.016839842 | M562: =(C562-C563)/C563 -> -0.006 | N562: =(D562-D563)/D563 -> -0.076864848 | O562: =(E562-E563)/E563 -> -0.066783626 | P562: =(F562-F563)/F563 -> -0.082746019 | Q562: =(G562-G563)/G563 -> -0.0591133
A563: 05/06/2022 | B563: 27.91 | C563: =_xlfn.XLOOKUP(A563, [1]report!$A$8:$A$2523, [1]report!$E$8:$E$2523, "n/A", 0) -> 40 | D563: =_xlfn.XLOOKUP(A563, [2]report!$A$8:$A$2521, [2]report!$E$8:$E$2521, "n/A", 0) -> 317.05 | E563: =_xlfn.XLOOKUP(A563, [3]report!$A$12:$A$2526, [3]report!$E$12:$E$2526, "n/A", 0) -> 85.5 | F563: =_xlfn.XLOOKUP(A563, [4]report!$A$12:$A$2526, [4]report!$E$12:$E$2526, "n/A",0) -> 38.31 | G563: =_xlfn.XLOOKUP(A563, [5]report!$A$12:$A$2526, [5]report!$E$12:$E$2526, "n/A",0) -> 14.21 | H563: 0.2 | I563: -0.49 | J563: -1.24 | K563: 0.001 | L563: =(B563-B564)/B564 -> -0.06090175 | M563: =(C563-C564)/C564 -> -0.0094105993 | N563: =(D563-D564)/D564 -> -0.077270081 | O563: =(E563-E564)/E564 -> -0.011217763 | P563: =(F563-F564)/F564 -> -0.02519084 | Q563: =(G563-G564)/G564 -> -0.0220234
A564: 05/05/2022 | B564: 29.72 | C564: =_xlfn.XLOOKUP(A564, [1]report!$A$8:$A$2523, [1]report!$E$8:$E$2523, "n/A", 0) -> 40.38 | D564: =_xlfn.XLOOKUP(A564, [2]report!$A$8:$A$2521, [2]report!$E$8:$E$2521, "n/A", 0) -> 343.6 | E564: =_xlfn.XLOOKUP(A564, [3]report!$A$12:$A$2526, [3]report!$E$12:$E$2526, "n/A", 0) -> 86.47 | F564: =_xlfn.XLOOKUP(A564, [4]report!$A$12:$A$2526, [4]report!$E$12:$E$2526, "n/A",0) -> 39.3 | G564: =_xlfn.XLOOKUP(A564, [5]report!$A$12:$A$2526, [5]report!$E$12:$E$2526, "n/A",0) -> 14.53 | H564: -3.54 | I564: -0.03 | J564: 1.31 | K564: 0.001 | L564: =(B564-B565)/B565 -> -0.015241882 | M564: =(C564-C565)/C565 -> -0.029793369 | N564: =(D564-D565)/D565 -> -0.057778265 | O564: =(E564-E565)/E565 -> -0.041565063 | P564: =(F564-F565)/F565 -> -0.04216427 | Q564: =(G564-G565)/G565 -> -0.030040053
A565: 05/04/2022 | B565: 30.18 | C565: =_xlfn.XLOOKUP(A565, [1]report!$A$8:$A$2523, [1]report!$E$8:$E$2523, "n/A", 0) -> 41.62 | D565: =_xlfn.XLOOKUP(A565, [2]report!$A$8:$A$2521, [2]report!$E$8:$E$2521, "n/A", 0) -> 364.67 | E565: =_xlfn.XLOOKUP(A565, [3]report!$A$12:$A$2526, [3]report!$E$12:$E$2526, "n/A", 0) -> 90.22 | F565: =_xlfn.XLOOKUP(A565, [4]report!$A$12:$A$2526, [4]report!$E$12:$E$2526, "n/A",0) -> 41.03 | G565: =_xlfn.XLOOKUP(A565, [5]report!$A$12:$A$2526, [5]report!$E$12:$E$2526, "n/A",0) -> 14.98 | H565: -0.85 | I565: -1.02 | J565: 1.79 | K565: 0.001 | L565: =(B565-B566)/B566 -> 0.010040161 | M565: =(C565-C566)/C566 -> 0.030963587 | N565: =(D565-D566)/D566 -> 0.02521788 | O565: =(E565-E566)/E566 -> 0.008608161 | P565: =(F565-F566)/F566 -> 0.0044063647 | Q565: =(G565-G566)/G566 -> 0.028846154
A566: 05/03/2022 | B566: 29.88 | C566: =_xlfn.XLOOKUP(A566, [1]report!$A$8:$A$2523, [1]report!$E$8:$E$2523, "n/A", 0) -> 40.37 | D566: =_xlfn.XLOOKUP(A566, [2]report!$A$8:$A$2521, [2]report!$E$8:$E$2521, "n/A", 0) -> 355.7 | E566: =_xlfn.XLOOKUP(A566, [3]report!$A$12:$A$2526, [3]report!$E$12:$E$2526, "n/A", 0) -> 89.45 | F566: =_xlfn.XLOOKUP(A566, [4]report!$A$12:$A$2526, [4]report!$E$12:$E$2526, "n/A",0) -> 40.85 | G566: =_xlfn.XLOOKUP(A566, [5]report!$A$12:$A$2526, [5]report!$E$12:$E$2526, "n/A",0) -> 14.56 | H566: -3.8 | I566: -0.25 | J566: 2.37 | K566: 0.001 | L566: =(B566-B567)/B567 -> -0.012884044 | M566: =(C566-C567)/C567 -> -0.0019777503 | N566: =(D566-D567)/D567 -> -0.014244541 | O566: =(E566-E567)/E567 -> -0.050928382 | P566: =(F566-F567)/F567 -> -0.026685728 | Q566: =(G566-G567)/G567 -> 0.020322355
A567: 05/02/2022 | B567: 30.27 | C567: =_xlfn.XLOOKUP(A567, [1]report!$A$8:$A$2523, [1]report!$E$8:$E$2523, "n/A", 0) -> 40.45 | D567: =_xlfn.XLOOKUP(A567, [2]report!$A$8:$A$2521, [2]report!$E$8:$E$2521, "n/A", 0) -> 360.84 | E567: =_xlfn.XLOOKUP(A567, [3]report!$A$12:$A$2526, [3]report!$E$12:$E$2526, "n/A", 0) -> 94.25 | F567: =_xlfn.XLOOKUP(A567, [4]report!$A$12:$A$2526, [4]report!$E$12:$E$2526, "n/A",0) -> 41.97 | G567: =_xlfn.XLOOKUP(A567, [5]report!$A$12:$A$2526, [5]report!$E$12:$E$2526, "n/A",0) -> 14.27 | H567: 3 | I567: -0.53 | J567: 0.34 | K567: 0.001 | L567: =(B567-B568)/B568 -> 0.039491758 | M567: =(C567-C568)/C568 -> 0.017354125 | N567: =(D567-D568)/D568 -> 0.017511209 | O567: =(E567-E568)/E568 -> -0.0074768324 | P567: =(F567-F568)/F568 -> 0.022660819 | Q567: =(G567-G568)/G568 -> 0.0077683616
A568: 04/29/2022 | B568: 29.12 | C568: =_xlfn.XLOOKUP(A568, [1]report!$A$8:$A$2523, [1]report!$E$8:$E$2523, "n/A", 0) -> 39.76 | D568: =_xlfn.XLOOKUP(A568, [2]report!$A$8:$A$2521, [2]report!$E$8:$E$2521, "n/A", 0) -> 354.63 | E568: =_xlfn.XLOOKUP(A568, [3]report!$A$12:$A$2526, [3]report!$E$12:$E$2526, "n/A", 0) -> 94.96 | F568: =_xlfn.XLOOKUP(A568, [4]report!$A$12:$A$2526, [4]report!$E$12:$E$2526, "n/A",0) -> 41.04 | G568: =_xlfn.XLOOKUP(A568, [5]report!$A$12:$A$2526, [5]report!$E$12:$E$2526, "n/A",0) -> 14.16 | H568: 0.41 | I568: 0.15 | J568: 1.64 | K568: 0.001 | L568: =(B568-B569)/B569 -> 0.0024096386 | M568: =(C568-C569)/C569 -> -0.046522782 | N568: =(D568-D569)/D569 -> -0.021521397 | O568: =(E568-E569)/E569 -> -0.032304086 | P568: =(F568-F569)/F569 -> -0.025409641 | Q568: =(G568-G569)/G569 -> -0.031463748
A569: 04/28/2022 | B569: 29.05 | C569: =_xlfn.XLOOKUP(A569, [1]report!$A$8:$A$2523, [1]report!$E$8:$E$2523, "n/A", 0) -> 41.7 | D569: =_xlfn.XLOOKUP(A569, [2]report!$A$8:$A$2521, [2]report!$E$8:$E$2521, "n/A", 0) -> 362.43 | E569: =_xlfn.XLOOKUP(A569, [3]report!$A$12:$A$2526, [3]report!$E$12:$E$2526, "n/A", 0) -> 98.13 | F569: =_xlfn.XLOOKUP(A569, [4]report!$A$12:$A$2526, [4]report!$E$12:$E$2526, "n/A",0) -> 42.11 | G569: =_xlfn.XLOOKUP(A569, [5]report!$A$12:$A$2526, [5]report!$E$12:$E$2526, "n/A",0) -> 14.62 | H569: 0.8 | I569: 0.39 | J569: -1.15 | K569: 0.001 | L569: =(B569-B570)/B570 -> 0.0041479433 | M569: =(C569-C570)/C570 -> -0.061867267 | N569: =(D569-D570)/D570 -> 0.02375572 | O569: =(E569-E570)/E570 -> 0.014263566 | P569: =(F569-F570)/F570 -> 0.043877045 | Q569: =(G569-G570)/G570 -> -0.015488215
A570: 04/27/2022 | B570: 28.93 | C570: =_xlfn.XLOOKUP(A570, [1]report!$A$8:$A$2523, [1]report!$E$8:$E$2523, "n/A", 0) -> 44.45 | D570: =_xlfn.XLOOKUP(A570, [2]report!$A$8:$A$2521, [2]report!$E$8:$E$2521, "n/A", 0) -> 354.02 | E570: =_xlfn.XLOOKUP(A570, [3]report!$A$12:$A$2526, [3]report!$E$12:$E$2526, "n/A", 0) -> 96.75 | F570: =_xlfn.XLOOKUP(A570, [4]report!$A$12:$A$2526, [4]report!$E$12:$E$2526, "n/A",0) -> 40.34 | G570: =_xlfn.XLOOKUP(A570, [5]report!$A$12:$A$2526, [5]report!$E$12:$E$2526, "n/A",0) -> 14.85 | H570: -3.53 | I570: 0.87 | J570: 0.59 | K570: 0.001 | L570: =(B570-B571)/B571 -> -0.014981273 | M570: =(C570-C571)/C571 -> -0.002692394 | N570: =(D570-D571)/D571 -> 0.0042265906 | O570: =(E570-E571)/E571 -> 0.0086530442 | P570: =(F570-F571)/F571 -> -0.00024783147 | Q570: =(G570-G571)/G571 -> 0.0095173351
A571: 04/26/2022 | B571: 29.37 | C571: =_xlfn.XLOOKUP(A571, [1]report!$A$8:$A$2523, [1]report!$E$8:$E$2523, "n/A", 0) -> 44.57 | D571: =_xlfn.XLOOKUP(A571, [2]report!$A$8:$A$2521, [2]report!$E$8:$E$2521, "n/A", 0) -> 352.53 | E571: =_xlfn.XLOOKUP(A571, [3]report!$A$12:$A$2526, [3]report!$E$12:$E$2526, "n/A", 0) -> 95.92 | F571: =_xlfn.XLOOKUP(A571, [4]report!$A$12:$A$2526, [4]report!$E$12:$E$2526, "n/A",0) -> 40.35 | G571: =_xlfn.XLOOKUP(A571, [5]report!$A$12:$A$2526, [5]report!$E$12:$E$2526, "n/A",0) -> 14.71 | H571: 2.44 | I571: -0.51 | J571: -0.44 | K571: 0.001 | L571: =(B571-B572)/B572 -> -0.058653846 | M571: =(C571-C572)/C572 -> -0.024939838 | N571: =(D571-D572)/D572 -> -0.04227227 | O571: =(E571-E572)/E572 -> -0.016406891 | P571: =(F571-F572)/F572 -> -0.039971449 | Q571: =(G571-G572)/G572 -> -0.031599737
A572: 04/25/2022 | B572: 31.2 | C572: =_xlfn.XLOOKUP(A572, [1]report!$A$8:$A$2523, [1]report!$E$8:$E$2523, "n/A", 0) -> 45.71 | D572: =_xlfn.XLOOKUP(A572, [2]report!$A$8:$A$2521, [2]report!$E$8:$E$2521, "n/A", 0) -> 368.09 | E572: =_xlfn.XLOOKUP(A572, [3]report!$A$12:$A$2526, [3]report!$E$12:$E$2526, "n/A", 0) -> 97.52 | F572: =_xlfn.XLOOKUP(A572, [4]report!$A$12:$A$2526, [4]report!$E$12:$E$2526, "n/A",0) -> 42.03 | G572: =_xlfn.XLOOKUP(A572, [5]report!$A$12:$A$2526, [5]report!$E$12:$E$2526, "n/A",0) -> 15.19 | H572: 0.12 | I572: -0.57 | J572: 0.35 | K572: 0.001 | L572: =(B572-B573)/B573 -> 0.0051546392 | M572: =(C572-C573)/C573 -> 0.007271926 | N572: =(D572-D573)/D573 -> 0.012181708 | O572: =(E572-E573)/E573 -> 0.028583483 | P572: =(F572-F573)/F573 -> 0.023125609 | Q572: =(G572-G573)/G573 -> 0.0039656312
A573: 04/22/2022 | B573: 31.04 | C573: =_xlfn.XLOOKUP(A573, [1]report!$A$8:$A$2523, [1]report!$E$8:$E$2523, "n/A", 0) -> 45.38 | D573: =_xlfn.XLOOKUP(A573, [2]report!$A$8:$A$2521, [2]report!$E$8:$E$2521, "n/A", 0) -> 363.66 | E573: =_xlfn.XLOOKUP(A573, [3]report!$A$12:$A$2526, [3]report!$E$12:$E$2526, "n/A", 0) -> 94.81 | F573: =_xlfn.XLOOKUP(A573, [4]report!$A$12:$A$2526, [4]report!$E$12:$E$2526, "n/A",0) -> 41.08 | G573: =_xlfn.XLOOKUP(A573, [5]report!$A$12:$A$2526, [5]report!$E$12:$E$2526, "n/A",0) -> 15.13 | H573: -3 | I573: -0.36 | J573: 1.78 | K573: 0.001 | L573: =(B573-B574)/B574 -> -0.039306716 | M573: =(C573-C574)/C574 -> -0.033233916 | N573: =(D573-D574)/D574 -> -0.036023857 | O573: =(E573-E574)/E574 -> -0.023181537 | P573: =(F573-F574)/F574 -> -0.025847759 | Q573: =(G573-G574)/G574 -> -0.036305732
... A923: 12/01/2020 | B923: 36.36 | C923: =_xlfn.XLOOKUP(A923, [1]report!$A$8:$A$2523, [1]report!$E$8:$E$2523, "n/A", 0) -> 51.02 | D923: =_xlfn.XLOOKUP(A923, [2]report!$A$8:$A$2521, [2]report!$E$8:$E$2521, "n/A", 0) -> 377.52 | E923: =_xlfn.XLOOKUP(A923, [3]report!$A$12:$A$2526, [3]report!$E$12:$E$2526, "n/A", 0) -> 73.18 | F923: =_xlfn.XLOOKUP(A923, [4]report!$A$12:$A$2526, [4]report!$E$12:$E$2526, "n/A",0) -> 28.81 | G923: =_xlfn.XLOOKUP(A923, [5]report!$A$12:$A$2526, [5]report!$E$12:$E$2526, "n/A",0) -> 9.24 | H923: 0.18 | I923: 0.54 | J923: -0.06 | K923: 0 | L923: =(B923-B924)/B924 -> 0.030612245 | M923: =(C923-C924)/C924 -> 0.015525478 | N923: =(D923-D924)/D924 -> 0 | O923: =(E923-E924)/E924 -> 0 | P923: =(F923-F924)/F924 -> 0 | Q923: =(G923-G924)/G924 -> 0
A924: 11/30/2020 | B924: 35.28 | C924: =_xlfn.XLOOKUP(A924, [1]report!$A$8:$A$2523, [1]report!$E$8:$E$2523, "n/A", 0) -> 50.24 | D924: 377.52 | E924: 73.18 | F924: 28.81 | G924: 9.24 | H924: 0.11 | I924: 0.21 | J924: 1.07 | K924: 0 | L924: =(B924-B925)/B925 -> 0.0061314701 | M924: =(C924-C925)/C925 -> -0.029178744 | N924: =(D924-D925)/D925 -> 0.033197406 | O924: =(E924-E925)/E925 -> -0.0047599619 | P924: =(F924-F925)/F925 -> 0.0066387142 | Q924: =(G924-G925)/G925 -> 0.01650165
A925: 11/27/2020 | B925: 35.065 | C925: =_xlfn.XLOOKUP(A925, [1]report!$A$8:$A$2523, [1]report!$E$8:$E$2523, "n/A", 0) -> 51.75 | D925: =_xlfn.XLOOKUP(A925, [2]report!$A$8:$A$2521, [2]report!$E$8:$E$2521, "n/A", 0) -> 365.39 | E925: =_xlfn.XLOOKUP(A925, [3]report!$A$12:$A$2526, [3]report!$E$12:$E$2526, "n/A", 0) -> 73.53 | F925: =_xlfn.XLOOKUP(A925, [4]report!$A$12:$A$2526, [4]report!$E$12:$E$2526, "n/A",0) -> 28.62 | G925: =_xlfn.XLOOKUP(A925, [5]report!$A$12:$A$2526, [5]report!$E$12:$E$2526, "n/A",0) -> 9.09 | H925: 0.98 | I925: -0.1 | J925: 0.55 | K925: 0 | L925: =(B925-B926)/B926 -> 0.0070361861 | M925: =(C925-C926)/C926 -> -0.00096525097 | N925: =(D925-D926)/D926 -> 0.021212968 | O925: =(E925-E926)/E926 -> 0.0025906736 | P925: =(F925-F926)/F926 -> 0.0081014442 | Q925: =(G925-G926)/G926 -> 0.0011013216
A926: 11/25/2020 | B926: 34.82 | C926: =_xlfn.XLOOKUP(A926, [1]report!$A$8:$A$2523, [1]report!$E$8:$E$2523, "n/A", 0) -> 51.8 | D926: =_xlfn.XLOOKUP(A926, [2]report!$A$8:$A$2521, [2]report!$E$8:$E$2521, "n/A", 0) -> 357.8 | E926: =_xlfn.XLOOKUP(A926, [3]report!$A$12:$A$2526, [3]report!$E$12:$E$2526, "n/A", 0) -> 73.34 | F926: =_xlfn.XLOOKUP(A926, [4]report!$A$12:$A$2526, [4]report!$E$12:$E$2526, "n/A",0) -> 28.39 | G926: =_xlfn.XLOOKUP(A926, [5]report!$A$12:$A$2526, [5]report!$E$12:$E$2526, "n/A",0) -> 9.08 | H926: -0.53 | I926: -1.54 | J926: -2.05 | K926: 0 | L926: =(B926-B927)/B927 -> 0.0089829035 | M926: =(C926-C927)/C927 -> -0.010317157 | N926: =(D926-D927)/D927 -> 0.023601774 | O926: =(E926-E927)/E927 -> -0.0095881161 | P926: =(F926-F927)/F927 -> -0.0021089631 | Q926: =(G926-G927)/G927 -> -0.039153439
A927: 11/24/2020 | B927: 34.51 | C927: =_xlfn.XLOOKUP(A927, [1]report!$A$8:$A$2523, [1]report!$E$8:$E$2523, "n/A", 0) -> 52.34 | D927: =_xlfn.XLOOKUP(A927, [2]report!$A$8:$A$2521, [2]report!$E$8:$E$2521, "n/A", 0) -> 349.55 | E927: =_xlfn.XLOOKUP(A927, [3]report!$A$12:$A$2526, [3]report!$E$12:$E$2526, "n/A", 0) -> 74.05 | F927: =_xlfn.XLOOKUP(A927, [4]report!$A$12:$A$2526, [4]report!$E$12:$E$2526, "n/A",0) -> 28.45 | G927: =_xlfn.XLOOKUP(A927, [5]report!$A$12:$A$2526, [5]report!$E$12:$E$2526, "n/A",0) -> 9.45 | H927: 0.43 | I927: 0.15 | J927: -1.62 | K927: 0 | L927: =(B927-B928)/B928 -> -0.0031773541 | M927: =(C927-C928)/C928 -> 0.050793013 | N927: =(D927-D928)/D928 -> 0.0029265773 | O927: =(E927-E928)/E928 -> 0.034217877 | P927: =(F927-F928)/F928 -> 0.087954111 | Q927: =(G927-G928)/G928 -> 0.066591422
A928: 11/23/2020 | B928: 34.62 | C928: =_xlfn.XLOOKUP(A928, [1]report!$A$8:$A$2523, [1]report!$E$8:$E$2523, "n/A", 0) -> 49.81 | D928: =_xlfn.XLOOKUP(A928, [2]report!$A$8:$A$2521, [2]report!$E$8:$E$2521, "n/A", 0) -> 348.53 | E928: =_xlfn.XLOOKUP(A928, [3]report!$A$12:$A$2526, [3]report!$E$12:$E$2526, "n/A", 0) -> 71.6 | F928: =_xlfn.XLOOKUP(A928, [4]report!$A$12:$A$2526, [4]report!$E$12:$E$2526, "n/A",0) -> 26.15 | G928: =_xlfn.XLOOKUP(A928, [5]report!$A$12:$A$2526, [5]report!$E$12:$E$2526, "n/A",0) -> 8.86 | H928: 0.03 | I928: -0.27 | J928: -1.34 | K928: 0 | L928: =(B928-B929)/B929 -> 0.018534863 | M928: =(C928-C929)/C929 -> 0.013016067 | N928: =(D928-D929)/D929 -> 0.0080696477 | O928: =(E928-E929)/E929 -> 0.03723019 | P928: =(F928-F929)/F929 -> -0.0022892026 | Q928: =(G928-G929)/G929 -> 0.013729977
A929: 11/20/2020 | B929: 33.99 | C929: =_xlfn.XLOOKUP(A929, [1]report!$A$8:$A$2523, [1]report!$E$8:$E$2523, "n/A", 0) -> 49.17 | D929: =_xlfn.XLOOKUP(A929, [2]report!$A$8:$A$2521, [2]report!$E$8:$E$2521, "n/A", 0) -> 345.74 | E929: =_xlfn.XLOOKUP(A929, [3]report!$A$12:$A$2526, [3]report!$E$12:$E$2526, "n/A", 0) -> 69.03 | F929: =_xlfn.XLOOKUP(A929, [4]report!$A$12:$A$2526, [4]report!$E$12:$E$2526, "n/A",0) -> 26.21 | G929: =_xlfn.XLOOKUP(A929, [5]report!$A$12:$A$2526, [5]report!$E$12:$E$2526, "n/A",0) -> 8.74 | H929: 1.56 | I929: 0.54 | J929: 2.76 | K929: 0 | L929: =(B929-B930)/B930 -> 0.016751421 | M929: =(C929-C930)/C930 -> -0.0062651576 | N929: =(D929-D930)/D930 -> 0.0033081834 | O929: =(E929-E930)/E930 -> -0.015263909 | P929: =(F929-F930)/F930 -> -0.037812041 | Q929: =(G929-G930)/G930 -> -0.0090702948
A930: 11/19/2020 | B930: 33.43 | C930: =_xlfn.XLOOKUP(A930, [1]report!$A$8:$A$2523, [1]report!$E$8:$E$2523, "n/A", 0) -> 49.48 | D930: =_xlfn.XLOOKUP(A930, [2]report!$A$8:$A$2521, [2]report!$E$8:$E$2521, "n/A", 0) -> 344.6 | E930: =_xlfn.XLOOKUP(A930, [3]report!$A$12:$A$2526, [3]report!$E$12:$E$2526, "n/A", 0) -> 70.1 | F930: =_xlfn.XLOOKUP(A930, [4]report!$A$12:$A$2526, [4]report!$E$12:$E$2526, "n/A",0) -> 27.24 | G930: =_xlfn.XLOOKUP(A930, [5]report!$A$12:$A$2526, [5]report!$E$12:$E$2526, "n/A",0) -> 8.82 | H930: 0.83 | I930: 1.4 | J930: 1.53 | K930: 0 | L930: =(B930-B931)/B931 -> 0.022324159 | M930: =(C930-C931)/C931 -> 0.0069190069 | N930: =(D930-D931)/D931 -> 0.022764372 | O930: =(E930-E931)/E931 -> 0.0022876752 | P930: =(F930-F931)/F931 -> 0.012263099 | Q930: =(G930-G931)/G931 -> 0
A931: 11/18/2020 | B931: 32.7 | C931: =_xlfn.XLOOKUP(A931, [1]report!$A$8:$A$2523, [1]report!$E$8:$E$2523, "n/A", 0) -> 49.14 | D931: =_xlfn.XLOOKUP(A931, [2]report!$A$8:$A$2521, [2]report!$E$8:$E$2521, "n/A", 0) -> 336.93 | E931: =_xlfn.XLOOKUP(A931, [3]report!$A$12:$A$2526, [3]report!$E$12:$E$2526, "n/A", 0) -> 69.94 | F931: =_xlfn.XLOOKUP(A931, [4]report!$A$12:$A$2526, [4]report!$E$12:$E$2526, "n/A",0) -> 26.91 | G931: =_xlfn.XLOOKUP(A931, [5]report!$A$12:$A$2526, [5]report!$E$12:$E$2526, "n/A",0) -> 8.82 | H931: -0.51 | I931: 0.6 | J931: -0.59 | K931: 0 | L931: =(B931-B932)/B932 -> 0.01269743 | M931: =(C931-C932)/C932 -> -0.012856569 | N931: =(D931-D932)/D932 -> -0.0043439716 | O931: =(E931-E932)/E932 -> -0.0066751882 | P931: =(F931-F932)/F932 -> 0.018546556 | Q931: =(G931-G932)/G932 -> 0.008
A932: 11/17/2020 | B932: 32.29 | C932: =_xlfn.XLOOKUP(A932, [1]report!$A$8:$A$2523, [1]report!$E$8:$E$2523, "n/A", 0) -> 49.78 | D932: =_xlfn.XLOOKUP(A932, [2]report!$A$8:$A$2521, [2]report!$E$8:$E$2521, "n/A", 0) -> 338.4 | E932: =_xlfn.XLOOKUP(A932, [3]report!$A$12:$A$2526, [3]report!$E$12:$E$2526, "n/A", 0) -> 70.41 | F932: =_xlfn.XLOOKUP(A932, [4]report!$A$12:$A$2526, [4]report!$E$12:$E$2526, "n/A",0) -> 26.42 | G932: =_xlfn.XLOOKUP(A932, [5]report!$A$12:$A$2526, [5]report!$E$12:$E$2526, "n/A",0) -> 8.75 | H932: 0.59 | I932: 0.27 | J932: -0.8 | K932: 0 | L932: =(B932-B933)/B933 -> 0.012225705 | M932: =(C932-C933)/C933 -> 0.00484457 | N932: =(D932-D933)/D933 -> 0.019983724 | O932: =(E932-E933)/E933 -> -0.014417693 | P932: =(F932-F933)/F933 -> -0.0033949453 | Q932: =(G932-G933)/G933 -> -0.0056818182
A933: 11/16/2020 | B933: 31.9 | C933: =_xlfn.XLOOKUP(A933, [1]report!$A$8:$A$2523, [1]report!$E$8:$E$2523, "n/A", 0) -> 49.54 | D933: =_xlfn.XLOOKUP(A933, [2]report!$A$8:$A$2521, [2]report!$E$8:$E$2521, "n/A", 0) -> 331.77 | E933: =_xlfn.XLOOKUP(A933, [3]report!$A$12:$A$2526, [3]report!$E$12:$E$2526, "n/A", 0) -> 71.44 | F933: =_xlfn.XLOOKUP(A933, [4]report!$A$12:$A$2526, [4]report!$E$12:$E$2526, "n/A",0) -> 26.51 | G933: =_xlfn.XLOOKUP(A933, [5]report!$A$12:$A$2526, [5]report!$E$12:$E$2526, "n/A",0) -> 8.8 | H933: -0.93 | I933: -0.03 | J933: -0.04 | K933: 0 | L933: =(B933-B934)/B934 -> 0.056291391 | M933: =(C933-C934)/C934 -> 0.011020408 | N933: =(D933-D934)/D934 -> 0.019419266 | O933: =(E933-E934)/E934 -> 0.034013605 | P933: =(F933-F934)/F934 -> 0.023552124 | Q933: =(G933-G934)/G934 -> 0.030444965
A934: 11/13/2020 | B934: 30.2 | C934: =_xlfn.XLOOKUP(A934, [1]report!$A$8:$A$2523, [1]report!$E$8:$E$2523, "n/A", 0) -> 49 | D934: =_xlfn.XLOOKUP(A934, [2]report!$A$8:$A$2521, [2]report!$E$8:$E$2521, "n/A", 0) -> 325.45 | E934: =_xlfn.XLOOKUP(A934, [3]report!$A$12:$A$2526, [3]report!$E$12:$E$2526, "n/A", 0) -> 69.09 | F934: =_xlfn.XLOOKUP(A934, [4]report!$A$12:$A$2526, [4]report!$E$12:$E$2526, "n/A",0) -> 25.9 | G934: =_xlfn.XLOOKUP(A934, [5]report!$A$12:$A$2526, [5]report!$E$12:$E$2526, "n/A",0) -> 8.54 | H934: -0.19 | I934: 0.58 | J934: 0.01 | K934: 0 | L934: =(B934-B935)/B935 -> 0.032478632 | M934: =(C934-C935)/C935 -> 0.021258858 | N934: =(D934-D935)/D935 -> -0.013518838 | O934: =(E934-E935)/E935 -> 0.049202733 | P934: =(F934-F935)/F935 -> 0.093288307 | Q934: =(G934-G935)/G935 -> 0.040194884
...

Sheet Date Gaps
A2: Date | B2: 0
A3: 08/01/2024 | B3: 1
B4: 1
B5: 1
A6: 07/31/2024 | B6: 2
B7: 2
B8: 2
A9: 07/30/2024 | B9: 3
B10: 3
B11: 3
A12: 07/29/2024 | B12: 4
B13: 4
B14: 4
A15: 07/26/2024 | B15: 5
B16: 5
B17: 5
A18: 07/25/2024 | B18: 6
B19: 6
B20: 6
A21: 07/24/2024 | B21: 7
B22: 7
B23: 7
A24: 07/23/2024 | B24: 8
B25: 8
B26: 8
A27: 07/22/2024 | B27: 9
B28: 9
B29: 9
A30: 07/19/2024 | B30: 10
B31: 10
B32: 10
A33: 07/18/2024 | B33: 11
B34: 11
B35: 11
A36: 07/17/2024 | B36: 12
B37: 12
B38: 12
A39: 07/16/2024 | B39: 13
B40: 13
B41: 13
...

Sheet FM1
A2: Date | B2: Row Offset | C2: 3 independent factors | D2: Paramount Coeff | E2: Comcast Coeff | F2: LuluLemon Coeff | G2: Hyatt Hotels Coeff | H2: MGM Resorts Coeff | I2: Ford Motors Coeff | K2: Avg Coef | L2: Para | M2: Comcast | N2: LuLu | O2: Hyatt | P2: MGM | Q2: Ford
